<mujoco model="summit_xls">
    <compiler angle="radian" meshdir="assets"/>

    <!--  For Mecanum wheel, Force motor must be applied -> dt must be 0.001 -->
    <option timestep="0.001" integrator="implicitfast"/>

    <default>
        <default class="summit_xls">
            <material specular="0.5" shininess="0.25"/>
            <joint armature="0.1" damping="1"/>
            <position inheritrange="1"/>
            <default class="visual">
                <geom type="mesh" group="2" contype="0" conaffinity="0"/>
            </default>
            <default class="collision">
                <geom type="mesh" group="3" mass="0" density="0"/>
            </default>
            <site size="0.001" rgba="0.5 0.5 0.5 0.3" group="4"/>
        </default>
    </default>
    
    <asset>
        <mesh name="summit_xls_chassis"           file="bases/xls/summit_xls_chassis.stl" />
        <mesh name="summit_xls_chapas_inox_tapas" file="bases/xls/summit_xls_chapas_inox_tapas.stl" />
        <mesh name="robotnik_logo_chasis"         file="bases/xls/robotnik_logo_chasis.stl" />
        <mesh name="summit_xls_omni_wheel_1"      file="wheels/omni_wheel_1.stl" />
        <mesh name="summit_xls_omni_wheel_2"      file="wheels/omni_wheel_2.stl" />
        <mesh name="structure_hokuyo"             file="structures/structure_hokuyo.stl" />
    </asset>

    <worldbody>
        <!-- Summit XL Steel -->
        <body name="base_footprint" pos="0 0 -0.009">
            <joint type="free" stiffness="0" damping="0" frictionloss="0" armature="0"/>
            
            <!-- BASE_LINK -->
            <body name="base" pos="0 0 0.127">
                <inertial pos="0 0 0" quat="1 0 0 0" mass="125.0" diaginertia="1.391 6.853 6.125" />
                <site name="xls_site"  size = "0.005" rgba = ".1 .1 .9 1" type = "sphere" />
                <geom type="mesh" rgba="0 0 0 1" mesh="summit_xls_chassis" contype="1" conaffinity="0" group="1"/>
    
                <!-- CHAPAS INOX TAPAS -->
                <geom type="mesh" pos="0.0 0 0.38062" quat="1 0 0 0" rgba="0.5 0.5 0.5 1" mesh="summit_xls_chapas_inox_tapas" contype="0" conaffinity="0" group="2"/>
    
                <!-- LOGO ROBOTNIK IZQUIERDO -->
                <geom type="mesh" pos="0.0 0.28931 0.29062" quat="1 0 0 0" rgba="0.5 0.5 0.5 1" mesh="robotnik_logo_chasis" contype="0" conaffinity="0" group="2"/>
    
                <!-- LOGO ROBOTNIK DERECHO -->
                <geom type="mesh" pos="0.0 -0.28931 0.29062" quat="0 0 0 1" rgba="0.5 0.5 0.5 1" mesh="robotnik_logo_chasis" contype="0" conaffinity="0" group="2"/>
    
                <!-- LOGO ROBOTNIK FRONTAL -->
                <geom type="mesh" pos="0.345 0.0 0.0" quat="-0.7071068 0 0 0.7071068" rgba="0.5 0.5 0.5 1" mesh="robotnik_logo_chasis" contype="0" conaffinity="0" group="2"/>
    
                <!-- LOGO ROBOTNIK TRASERO -->
                <geom type="mesh" pos="-0.345 0.0 0.0" quat="0.7071068 0 0 0.7071068" rgba="0.5 0.5 0.5 1" mesh="robotnik_logo_chasis" contype="0" conaffinity="0" group="2"/>
    
                <!-- Wheels -->
                <body name="front_right_wheel_intermediate_link" pos="0.2225 -0.2045 0">
                    <inertial pos="0 0 0" quat="0.707107 0 0 0.707107" mass="6.5" diaginertia="0.0524193 0.0303095 0.0303095" />
                    <joint name="front_right_wheel" pos="0 0 0" axis="0 1 0" />
                    <geom size="0.120 0.0435" quat="0.707107 0.707107 0 0" type="cylinder" rgba="0.2 0.2 0.2 0.5" contype="1" conaffinity="0" group="3" />
                    <geom type="mesh" mesh="summit_xls_omni_wheel_2" contype="0" conaffinity="0" group="2" rgba="0.2 0.2 0.2 1"/>
                
    
                    <body name="front_right_roller_0_link" pos="0.04385159698893431 0.0 0.011749999999999998">
                        <joint name="front_right_slipping_0_joint" type="hinge" pos="0 0 0" axis="-0.006296806022131382 0.0435 0.023499999999999997" damping="0.1" limited="false" actuatorfrclimited="false"/>
                        <inertial pos="0 0 0" quat="0.711549 0.711549 0 0 " mass="0.001" diaginertia="0.00001 0.00001 0.00001" />
                        <geom size="0.08" quat="1 0 0 0" type="sphere" rgba="0.2 0.2 0.2 1" contype="1" conaffinity="0" group="3"/>
                    </body>
    
                    <body name="front_right_roller_1_link" pos="0.03210159698893431 0.0 0.032101596988934306">
                        <joint name="front_right_slipping_1_joint" type="hinge" pos="0 0 0" axis="-0.01720319397786861 0.0435 0.017203193977868615" damping="0.1" limited="false" actuatorfrclimited="false"/>
                        <inertial pos="0 0 0" quat="0.711549 0.711549 0 0 " mass="0.001" diaginertia="0.00001 0.00001 0.00001" />
                        <geom size="0.08" quat="1 0 0 0" type="sphere" rgba="0.2 0.2 0.2 1" contype="1" conaffinity="0" group="3"/>
                    </body>
    
                    <body name="front_right_roller_2_link" pos="0.011750000000000005 0.0 0.0438515969889343">
                        <joint name="front_right_slipping_2_joint" type="hinge" pos="0 0 0" axis="-0.023500000000000004 0.0435 0.006296806022131389" damping="0.1" limited="false" actuatorfrclimited="false"/>
                        <inertial pos="0 0 0" quat="0.711549 0.711549 0 0 " mass="0.001" diaginertia="0.00001 0.00001 0.00001" />
                        <geom size="0.08" quat="1 0 0 0" type="sphere" rgba="0.2 0.2 0.2 1" contype="1" conaffinity="0" group="3"/>
                    </body>
    
                    <body name="front_right_roller_3_link" pos="-0.011749999999999993 0.0 0.04385159698893431">
                        <joint name="front_right_slipping_3_joint" type="hinge" pos="0 0 0" axis="-0.023499999999999993 0.0435 -0.006296806022131382" damping="0.1" limited="false" actuatorfrclimited="false"/>
                        <inertial pos="0 0 0" quat="0.711549 0.711549 0 0 " mass="0.001" diaginertia="0.00001 0.00001 0.00001" />
                        <geom size="0.08" quat="1 0 0 0" type="sphere" rgba="0.2 0.2 0.2 1" contype="1" conaffinity="0" group="3"/>
                    </body>
    
                    <body name="front_right_roller_4_link" pos="-0.0321015969889343 0.0 0.03210159698893432">
                        <joint name="front_right_slipping_4_joint" type="hinge" pos="0 0 0" axis="-0.01720319397786862 0.0435 -0.0172031939778686" damping="0.1" limited="false" actuatorfrclimited="false"/>
                        <inertial pos="0 0 0" quat="0.711549 0.711549 0 0 " mass="0.001" diaginertia="0.00001 0.00001 0.00001" />
                        <geom size="0.08" quat="1 0 0 0" type="sphere" rgba="0.2 0.2 0.2 1" contype="1" conaffinity="0" group="3"/>
                    </body>
    
                    <body name="front_right_roller_5_link" pos="-0.0438515969889343 0.0 0.011750000000000012">
                        <joint name="front_right_slipping_5_joint" type="hinge" pos="0 0 0" axis="-0.006296806022131389 0.0435 -0.02350000000000001" damping="0.1" limited="false" actuatorfrclimited="false"/>
                        <inertial pos="0 0 0" quat="0.711549 0.711549 0 0 " mass="0.001" diaginertia="0.00001 0.00001 0.00001" />
                        <geom size="0.08" quat="1 0 0 0" type="sphere" rgba="0.2 0.2 0.2 1" contype="1" conaffinity="0" group="3"/>
                    </body>
    
                    <body name="front_right_roller_6_link" pos="-0.043851596988934316 0.0 -0.011749999999999991">
                        <joint name="front_right_slipping_6_joint" type="hinge" pos="0 0 0" axis="0.006296806022131375 0.0435 -0.023499999999999993" damping="0.1" limited="false" actuatorfrclimited="false"/>
                        <inertial pos="0 0 0" quat="0.711549 0.711549 0 0 " mass="0.001" diaginertia="0.00001 0.00001 0.00001" />
                        <geom size="0.08" quat="1 0 0 0" type="sphere" rgba="0.2 0.2 0.2 1" contype="1" conaffinity="0" group="3"/>
                    </body>
    
                    <body name="front_right_roller_7_link" pos="-0.03210159698893432 0.0 -0.03210159698893429">
                        <joint name="front_right_slipping_7_joint" type="hinge" pos="0 0 0" axis="0.017203193977868604 0.0435 -0.017203193977868618" damping="0.1" limited="false" actuatorfrclimited="false"/>
                        <inertial pos="0 0 0" quat="0.711549 0.711549 0 0 " mass="0.001" diaginertia="0.00001 0.00001 0.00001" />
                        <geom size="0.08" quat="1 0 0 0" type="sphere" rgba="0.2 0.2 0.2 1" contype="1" conaffinity="0" group="3"/>
                    </body>
    
                    <body name="front_right_roller_8_link" pos="-0.011750000000000014 0.0 -0.0438515969889343">
                        <joint name="front_right_slipping_8_joint" type="hinge" pos="0 0 0" axis="0.023500000000000014 0.0435 -0.006296806022131396" damping="0.1" limited="false" actuatorfrclimited="false"/>
                        <inertial pos="0 0 0" quat="0.711549 0.711549 0 0 " mass="0.001" diaginertia="0.00001 0.00001 0.00001" />
                        <geom size="0.08" quat="1 0 0 0" type="sphere" rgba="0.2 0.2 0.2 1" contype="1" conaffinity="0" group="3"/>
                    </body>
    
                    <body name="front_right_roller_9_link" pos="0.01174999999999998 0.0 -0.043851596988934316">
                        <joint name="front_right_slipping_9_joint" type="hinge" pos="0 0 0" axis="0.023499999999999976 0.0435 0.006296806022131368" damping="0.1" limited="false" actuatorfrclimited="false"/>
                        <inertial pos="0 0 0" quat="0.711549 0.711549 0 0 " mass="0.001" diaginertia="0.00001 0.00001 0.00001" />
                        <geom size="0.08" quat="1 0 0 0" type="sphere" rgba="0.2 0.2 0.2 1" contype="1" conaffinity="0" group="3"/>
                    </body>
    
                    <body name="front_right_roller_10_link" pos="0.032101596988934285 0.0 -0.032101596988934326">
                        <joint name="front_right_slipping_10_joint" type="hinge" pos="0 0 0" axis="0.017203193977868635 0.0435 0.01720319397786861" damping="0.1" limited="false" actuatorfrclimited="false"/>
                        <inertial pos="0 0 0" quat="0.711549 0.711549 0 0 " mass="0.001" diaginertia="0.00001 0.00001 0.00001" />
                        <geom size="0.08" quat="1 0 0 0" type="sphere" rgba="0.2 0.2 0.2 1" contype="1" conaffinity="0" group="3"/>
                    </body>
    
                    <body name="front_right_roller_11_link" pos="0.0438515969889343 0.0 -0.01175000000000001">
                        <joint name="front_right_slipping_11_joint" type="hinge" pos="0 0 0" axis="0.006296806022131396 0.0435 0.02350000000000002" damping="0.1" limited="false" actuatorfrclimited="false"/>
                        <inertial pos="0 0 0" quat="0.711549 0.711549 0 0 " mass="0.001" diaginertia="0.00001 0.00001 0.00001" />
                        <geom size="0.08" quat="1 0 0 0" type="sphere" rgba="0.2 0.2 0.2 1" contype="1" conaffinity="0" group="3"/>
                    </body>
                </body>
    
                <body name="front_left_wheel_intermediate_link" pos="0.2225 0.2045 0">
                    <inertial pos="0 0 0" quat="0.707107 0 0 0.707107" mass="6.5" diaginertia="0.0524193 0.0303095 0.0303095" />
                    <joint name="front_left_wheel" pos="0 0 0" axis="0 1 0" />
                    <geom size="0.120 0.0435" quat="0.707107 0.707107 0 0" type="cylinder" rgba="0.2 0.2 0.2 0.5" contype="1" conaffinity="0" group="3"/>
                    <geom type="mesh" mesh="summit_xls_omni_wheel_1" contype="0" conaffinity="0" group="2" rgba="0.2 0.2 0.2 1"/>
    
    
                    <body name="front_left_roller_0_link" pos="0.0438515969889343 0.0 -0.01175000000000001">
                        <joint name="front_left_slipping_0_joint" type="hinge" pos="0 0 0" axis="-0.006296806022131396 0.0435 -0.02350000000000002" damping="0.1" limited="false" actuatorfrclimited="false"/>
                        <inertial pos="0 0 0" quat="0.711549 0.711549 0 0 " mass="0.001" diaginertia="0.00001 0.00001 0.00001" />
                        <geom size="0.08" quat="1 0 0 0" type="sphere" rgba="0.2 0.2 0.2 1" contype="1" conaffinity="0" group="3"/>
                    </body>
    
                    <body name="front_left_roller_1_link" pos="0.04385159698893431 0.0 0.011749999999999998">
                        <joint name="front_left_slipping_1_joint" type="hinge" pos="0 0 0" axis="0.006296806022131382 0.0435 -0.023499999999999997" damping="0.1" limited="false" actuatorfrclimited="false"/>
                        <inertial pos="0 0 0" quat="0.711549 0.711549 0 0 " mass="0.001" diaginertia="0.00001 0.00001 0.00001" />
                        <geom size="0.08" quat="1 0 0 0" type="sphere" rgba="0.2 0.2 0.2 1" contype="1" conaffinity="0" group="3"/>
                    </body>
    
                    <body name="front_left_roller_2_link" pos="0.03210159698893431 0.0 0.032101596988934306">
                        <joint name="front_left_slipping_2_joint" type="hinge" pos="0 0 0" axis="0.01720319397786861 0.0435 -0.017203193977868615" damping="0.1" limited="false" actuatorfrclimited="false"/>
                        <inertial pos="0 0 0" quat="0.711549 0.711549 0 0 " mass="0.001" diaginertia="0.00001 0.00001 0.00001" />
                        <geom size="0.08" quat="1 0 0 0" type="sphere" rgba="0.2 0.2 0.2 1" contype="1" conaffinity="0" group="3"/>
                    </body>
    
                    <body name="front_left_roller_3_link" pos="0.011750000000000005 0.0 0.0438515969889343">
                        <joint name="front_left_slipping_3_joint" type="hinge" pos="0 0 0" axis="0.023500000000000004 0.0435 -0.006296806022131389" damping="0.1" limited="false" actuatorfrclimited="false"/>
                        <inertial pos="0 0 0" quat="0.711549 0.711549 0 0 " mass="0.001" diaginertia="0.00001 0.00001 0.00001" />
                        <geom size="0.08" quat="1 0 0 0" type="sphere" rgba="0.2 0.2 0.2 1" contype="1" conaffinity="0" group="3"/>
                    </body>
    
                    <body name="front_left_roller_4_link" pos="-0.011749999999999993 0.0 0.04385159698893431">
                        <joint name="front_left_slipping_4_joint" type="hinge" pos="0 0 0" axis="0.023499999999999993 0.0435 0.006296806022131382" damping="0.1" limited="false" actuatorfrclimited="false"/>
                        <inertial pos="0 0 0" quat="0.711549 0.711549 0 0 " mass="0.001" diaginertia="0.00001 0.00001 0.00001" />
                        <geom size="0.08" quat="1 0 0 0" type="sphere" rgba="0.2 0.2 0.2 1" contype="1" conaffinity="0" group="3"/>
                    </body>
    
                    <body name="front_left_roller_5_link" pos="-0.0321015969889343 0.0 0.03210159698893432">
                        <joint name="front_left_slipping_5_joint" type="hinge" pos="0 0 0" axis="0.01720319397786862 0.0435 0.0172031939778686" damping="0.1" limited="false" actuatorfrclimited="false"/>
                        <inertial pos="0 0 0" quat="0.711549 0.711549 0 0 " mass="0.001" diaginertia="0.00001 0.00001 0.00001" />
                        <geom size="0.08" quat="1 0 0 0" type="sphere" rgba="0.2 0.2 0.2 1" contype="1" conaffinity="0" group="3"/>
                    </body>
    
                    <body name="front_left_roller_6_link" pos="-0.0438515969889343 0.0 0.01175000000000001">
                        <joint name="front_left_slipping_6_joint" type="hinge" pos="0 0 0" axis="0.006296806022131389 0.0435 0.02350000000000001" damping="0.1" limited="false" actuatorfrclimited="false"/>
                        <inertial pos="0 0 0" quat="0.711549 0.711549 0 0 " mass="0.001" diaginertia="0.00001 0.00001 0.00001" />
                        <geom size="0.08" quat="1 0 0 0" type="sphere" rgba="0.2 0.2 0.2 1" contype="1" conaffinity="0" group="3"/>
                    </body>
    
                    <body name="front_left_roller_7_link" pos="-0.043851596988934316 0.0 -0.01174999999999999">
                        <joint name="front_left_slipping_7_joint" type="hinge" pos="0 0 0" axis="-0.006296806022131375 0.0435 0.023499999999999993" damping="0.1" limited="false" actuatorfrclimited="false"/>
                        <inertial pos="0 0 0" quat="0.711549 0.711549 0 0 " mass="0.001" diaginertia="0.00001 0.00001 0.00001" />
                        <geom size="0.08" quat="1 0 0 0" type="sphere" rgba="0.2 0.2 0.2 1" contype="1" conaffinity="0" group="3"/>
                    </body>
    
                    <body name="front_left_roller_8_link" pos="-0.03210159698893432 0.0 -0.03210159698893429">
                        <joint name="front_left_slipping_8_joint" type="hinge" pos="0 0 0" axis="-0.017203193977868604 0.0435 0.017203193977868618" damping="0.1" limited="false" actuatorfrclimited="false"/>
                        <inertial pos="0 0 0" quat="0.711549 0.711549 0 0 " mass="0.001" diaginertia="0.00001 0.00001 0.00001" />
                        <geom size="0.08" quat="1 0 0 0" type="sphere" rgba="0.2 0.2 0.2 1" contype="1" conaffinity="0" group="3"/>
                    </body>
    
                    <body name="front_left_roller_9_link" pos="-0.011750000000000016 0.0 -0.0438515969889343">
                        <joint name="front_left_slipping_9_joint" type="hinge" pos="0 0 0" axis="-0.023500000000000014 0.0435 0.006296806022131396" damping="0.1" limited="false" actuatorfrclimited="false"/>
                        <inertial pos="0 0 0" quat="0.711549 0.711549 0 0 " mass="0.001" diaginertia="0.00001 0.00001 0.00001" />
                        <geom size="0.08" quat="1 0 0 0" type="sphere" rgba="0.2 0.2 0.2 1" contype="1" conaffinity="0" group="3"/>
                    </body>
    
                    <body name="front_left_roller_10_link" pos="0.011749999999999981 0.0 -0.043851596988934316">
                        <joint name="front_left_slipping_10_joint" type="hinge" pos="0 0 0" axis="-0.023499999999999976 0.0435 -0.006296806022131368" damping="0.1" limited="false" actuatorfrclimited="false"/>
                        <inertial pos="0 0 0" quat="0.711549 0.711549 0 0 " mass="0.001" diaginertia="0.00001 0.00001 0.00001" />
                        <geom size="0.08" quat="1 0 0 0" type="sphere" rgba="0.2 0.2 0.2 1" contype="1" conaffinity="0" group="3"/>
                    </body>
    
                    <body name="front_left_roller_11_link" pos="0.032101596988934285 0.0 -0.032101596988934326">
                        <joint name="front_left_slipping_11_joint" type="hinge" pos="0 0 0" axis="-0.017203193977868635 0.0435 -0.01720319397786861" damping="0.1" limited="false" actuatorfrclimited="false"/>
                        <inertial pos="0 0 0" quat="0.711549 0.711549 0 0 " mass="0.001" diaginertia="0.00001 0.00001 0.00001" />
                        <geom size="0.08" quat="1 0 0 0" type="sphere" rgba="0.2 0.2 0.2 1" contype="1" conaffinity="0" group="3"/>
                    </body>
                </body>
    
                <body name="rear_right_wheel_intermediate_link" pos="-0.2225 -0.2045 0">
                    <inertial pos="0 0 0" quat="0.707107 0 0 0.707107" mass="6.5" diaginertia="0.0524193 0.0303095 0.0303095" />
                    <joint name="rear_right_wheel" pos="0 0 0" axis="0 1 0" />
                    <geom size="0.120 0.0435" quat="0.707107 0.707107 0 0" type="cylinder" rgba="0.2 0.2 0.2 0.5" contype="1" conaffinity="0" group="3"/>
                    <geom type="mesh" mesh="summit_xls_omni_wheel_1" contype="0" conaffinity="0" group="2" rgba="0.2 0.2 0.2 1"/>
    
    
                    <body name="rear_right_roller_0_link" pos="0.0438515969889343 0.0 -0.01175000000000001">
                        <joint name="rear_right_slipping_0_joint" type="hinge" pos="0 0 0" axis="-0.006296806022131396 0.0435 -0.02350000000000002" damping="0.1" limited="false" actuatorfrclimited="false"/>
                        <inertial pos="0 0 0" quat="0.711549 0.711549 0 0 " mass="0.001" diaginertia="0.00001 0.00001 0.00001" />
                        <geom size="0.08" quat="1 0 0 0" type="sphere" rgba="0.2 0.2 0.2 1" contype="1" conaffinity="0" group="3"/>
                    </body>
    
                    <body name="rear_right_roller_1_link" pos="0.04385159698893431 0.0 0.011749999999999998">
                        <joint name="rear_right_slipping_1_joint" type="hinge" pos="0 0 0" axis="0.006296806022131382 0.0435 -0.023499999999999997" damping="0.1" limited="false" actuatorfrclimited="false"/>
                        <inertial pos="0 0 0" quat="0.711549 0.711549 0 0 " mass="0.001" diaginertia="0.00001 0.00001 0.00001" />
                        <geom size="0.08" quat="1 0 0 0" type="sphere" rgba="0.2 0.2 0.2 1" contype="1" conaffinity="0" group="3"/>
                    </body>
    
                    <body name="rear_right_roller_2_link" pos="0.03210159698893431 0.0 0.032101596988934306">
                        <joint name="rear_right_slipping_2_joint" type="hinge" pos="0 0 0" axis="0.01720319397786861 0.0435 -0.017203193977868615" damping="0.1" limited="false" actuatorfrclimited="false"/>
                        <inertial pos="0 0 0" quat="0.711549 0.711549 0 0 " mass="0.001" diaginertia="0.00001 0.00001 0.00001" />
                        <geom size="0.08" quat="1 0 0 0" type="sphere" rgba="0.2 0.2 0.2 1" contype="1" conaffinity="0" group="3"/>
                    </body>
    
                    <body name="rear_right_roller_3_link" pos="0.011750000000000005 0.0 0.0438515969889343">
                        <joint name="rear_right_slipping_3_joint" type="hinge" pos="0 0 0" axis="0.023500000000000004 0.0435 -0.006296806022131389" damping="0.1" limited="false" actuatorfrclimited="false"/>
                        <inertial pos="0 0 0" quat="0.711549 0.711549 0 0 " mass="0.001" diaginertia="0.00001 0.00001 0.00001" />
                        <geom size="0.08" quat="1 0 0 0" type="sphere" rgba="0.2 0.2 0.2 1" contype="1" conaffinity="0" group="3"/>
                    </body>
    
                    <body name="rear_right_roller_4_link" pos="-0.011749999999999993 0.0 0.04385159698893431">
                        <joint name="rear_right_slipping_4_joint" type="hinge" pos="0 0 0" axis="0.023499999999999993 0.0435 0.006296806022131382" damping="0.1" limited="false" actuatorfrclimited="false"/>
                        <inertial pos="0 0 0" quat="0.711549 0.711549 0 0 " mass="0.001" diaginertia="0.00001 0.00001 0.00001" />
                        <geom size="0.08" quat="1 0 0 0" type="sphere" rgba="0.2 0.2 0.2 1" contype="1" conaffinity="0" group="3"/>
                    </body>
    
                    <body name="rear_right_roller_5_link" pos="-0.0321015969889343 0.0 0.03210159698893432">
                        <joint name="rear_right_slipping_5_joint" type="hinge" pos="0 0 0" axis="0.01720319397786862 0.0435 0.0172031939778686" damping="0.1" limited="false" actuatorfrclimited="false"/>
                        <inertial pos="0 0 0" quat="0.711549 0.711549 0 0 " mass="0.001" diaginertia="0.00001 0.00001 0.00001" />
                        <geom size="0.08" quat="1 0 0 0" type="sphere" rgba="0.2 0.2 0.2 1" contype="1" conaffinity="0" group="3"/>
                    </body>
    
                    <body name="rear_right_roller_6_link" pos="-0.0438515969889343 0.0 0.01175000000000001">
                        <joint name="rear_right_slipping_6_joint" type="hinge" pos="0 0 0" axis="0.006296806022131389 0.0435 0.02350000000000001" damping="0.1" limited="false" actuatorfrclimited="false"/>
                        <inertial pos="0 0 0" quat="0.711549 0.711549 0 0 " mass="0.001" diaginertia="0.00001 0.00001 0.00001" />
                        <geom size="0.08" quat="1 0 0 0" type="sphere" rgba="0.2 0.2 0.2 1" contype="1" conaffinity="0" group="3"/>
                    </body>
    
                    <body name="rear_right_roller_7_link" pos="-0.043851596988934316 0.0 -0.01174999999999999">
                        <joint name="rear_right_slipping_7_joint" type="hinge" pos="0 0 0" axis="-0.006296806022131375 0.0435 0.023499999999999993" damping="0.1" limited="false" actuatorfrclimited="false"/>
                        <inertial pos="0 0 0" quat="0.711549 0.711549 0 0 " mass="0.001" diaginertia="0.00001 0.00001 0.00001" />
                        <geom size="0.08" quat="1 0 0 0" type="sphere" rgba="0.2 0.2 0.2 1" contype="1" conaffinity="0" group="3"/>
                    </body>
    
                    <body name="rear_right_roller_8_link" pos="-0.03210159698893432 0.0 -0.03210159698893429">
                        <joint name="rear_right_slipping_8_joint" type="hinge" pos="0 0 0" axis="-0.017203193977868604 0.0435 0.017203193977868618" damping="0.1" limited="false" actuatorfrclimited="false"/>
                        <inertial pos="0 0 0" quat="0.711549 0.711549 0 0 " mass="0.001" diaginertia="0.00001 0.00001 0.00001" />
                        <geom size="0.08" quat="1 0 0 0" type="sphere" rgba="0.2 0.2 0.2 1" contype="1" conaffinity="0" group="3"/>
                    </body>
    
                    <body name="rear_right_roller_9_link" pos="-0.011750000000000016 0.0 -0.0438515969889343">
                        <joint name="rear_right_slipping_9_joint" type="hinge" pos="0 0 0" axis="-0.023500000000000014 0.0435 0.006296806022131396" damping="0.1" limited="false" actuatorfrclimited="false"/>
                        <inertial pos="0 0 0" quat="0.711549 0.711549 0 0 " mass="0.001" diaginertia="0.00001 0.00001 0.00001" />
                        <geom size="0.08" quat="1 0 0 0" type="sphere" rgba="0.2 0.2 0.2 1" contype="1" conaffinity="0" group="3"/>
                    </body>
    
                    <body name="rear_right_roller_10_link" pos="0.011749999999999981 0.0 -0.043851596988934316">
                        <joint name="rear_right_slipping_10_joint" type="hinge" pos="0 0 0" axis="-0.023499999999999976 0.0435 -0.006296806022131368" damping="0.1" limited="false" actuatorfrclimited="false"/>
                        <inertial pos="0 0 0" quat="0.711549 0.711549 0 0 " mass="0.001" diaginertia="0.00001 0.00001 0.00001" />
                        <geom size="0.08" quat="1 0 0 0" type="sphere" rgba="0.2 0.2 0.2 1" contype="1" conaffinity="0" group="3"/>
                    </body>
    
                    <body name="rear_right_roller_11_link" pos="0.032101596988934285 0.0 -0.032101596988934326">
                        <joint name="rear_right_slipping_11_joint" type="hinge" pos="0 0 0" axis="-0.017203193977868635 0.0435 -0.01720319397786861" damping="0.1" limited="false" actuatorfrclimited="false"/>
                        <inertial pos="0 0 0" quat="0.711549 0.711549 0 0 " mass="0.001" diaginertia="0.00001 0.00001 0.00001" />
                        <geom size="0.08" quat="1 0 0 0" type="sphere" rgba="0.2 0.2 0.2 1" contype="1" conaffinity="0" group="3"/>
                    </body>
                </body>
    
                <body name="rear_left_wheel_intermediate_link" pos="-0.2225 0.2045 0">
                    <inertial pos="0 0 0" quat="0.707107 0 0 0.707107" mass="6.5" diaginertia="0.0524193 0.0303095 0.0303095" />
                    <joint name="rear_left_wheel" pos="0 0 0" axis="0 1 0" />
                    <geom size="0.120 0.0435" quat="0.707107 0.707107 0 0" type="cylinder" rgba="0.2 0.2 0.2 0.5" contype="1" conaffinity="0" group="3"/>
                    <geom type="mesh" mesh="summit_xls_omni_wheel_2" contype="0" conaffinity="0" group="2" rgba="0.2 0.2 0.2 1"/>
    
    
                    <body name="rear_left_roller_0_link" pos="0.04385159698893431 0.0 0.011749999999999998">
                        <joint name="rear_left_slipping_0_joint" type="hinge" pos="0 0 0" axis="-0.006296806022131382 0.0435 0.023499999999999997" damping="0.1" limited="false" actuatorfrclimited="false"/>
                        <inertial pos="0 0 0" quat="0.711549 0.711549 0 0 " mass="0.001" diaginertia="0.00001 0.00001 0.00001" />
                        <geom size="0.08" quat="1 0 0 0" type="sphere" rgba="0.2 0.2 0.2 1" contype="1" conaffinity="0" group="3"/>
                    </body>
    
                    <body name="rear_left_roller_1_link" pos="0.03210159698893431 0.0 0.032101596988934306">
                        <joint name="rear_left_slipping_1_joint" type="hinge" pos="0 0 0" axis="-0.01720319397786861 0.0435 0.017203193977868615" damping="0.1" limited="false" actuatorfrclimited="false"/>
                        <inertial pos="0 0 0" quat="0.711549 0.711549 0 0 " mass="0.001" diaginertia="0.00001 0.00001 0.00001" />
                        <geom size="0.08" quat="1 0 0 0" type="sphere" rgba="0.2 0.2 0.2 1" contype="1" conaffinity="0" group="3"/>
                    </body>
    
                    <body name="rear_left_roller_2_link" pos="0.011750000000000005 0.0 0.0438515969889343">
                        <joint name="rear_left_slipping_2_joint" type="hinge" pos="0 0 0" axis="-0.023500000000000004 0.0435 0.006296806022131389" damping="0.1" limited="false" actuatorfrclimited="false"/>
                        <inertial pos="0 0 0" quat="0.711549 0.711549 0 0 " mass="0.001" diaginertia="0.00001 0.00001 0.00001" />
                        <geom size="0.08" quat="1 0 0 0" type="sphere" rgba="0.2 0.2 0.2 1" contype="1" conaffinity="0" group="3"/>
                    </body>
    
                    <body name="rear_left_roller_3_link" pos="-0.011749999999999993 0.0 0.04385159698893431">
                        <joint name="rear_left_slipping_3_joint" type="hinge" pos="0 0 0" axis="-0.023499999999999993 0.0435 -0.006296806022131382" damping="0.1" limited="false" actuatorfrclimited="false"/>
                        <inertial pos="0 0 0" quat="0.711549 0.711549 0 0 " mass="0.001" diaginertia="0.00001 0.00001 0.00001" />
                        <geom size="0.08" quat="1 0 0 0" type="sphere" rgba="0.2 0.2 0.2 1" contype="1" conaffinity="0" group="3"/>
                    </body>
    
                    <body name="rear_left_roller_4_link" pos="-0.0321015969889343 0.0 0.03210159698893432">
                        <joint name="rear_left_slipping_4_joint" type="hinge" pos="0 0 0" axis="-0.01720319397786862 0.0435 -0.0172031939778686" damping="0.1" limited="false" actuatorfrclimited="false"/>
                        <inertial pos="0 0 0" quat="0.711549 0.711549 0 0 " mass="0.001" diaginertia="0.00001 0.00001 0.00001" />
                        <geom size="0.08" quat="1 0 0 0" type="sphere" rgba="0.2 0.2 0.2 1" contype="1" conaffinity="0" group="3"/>
                    </body>
    
                    <body name="rear_left_roller_5_link" pos="-0.0438515969889343 0.0 0.011750000000000012">
                        <joint name="rear_left_slipping_5_joint" type="hinge" pos="0 0 0" axis="-0.006296806022131389 0.0435 -0.02350000000000001" damping="0.1" limited="false" actuatorfrclimited="false"/>
                        <inertial pos="0 0 0" quat="0.711549 0.711549 0 0 " mass="0.001" diaginertia="0.00001 0.00001 0.00001" />
                        <geom size="0.08" quat="1 0 0 0" type="sphere" rgba="0.2 0.2 0.2 1" contype="1" conaffinity="0" group="3"/>
                    </body>
    
                    <body name="rear_left_roller_6_link" pos="-0.043851596988934316 0.0 -0.011749999999999991">
                        <joint name="rear_left_slipping_6_joint" type="hinge" pos="0 0 0" axis="0.006296806022131375 0.0435 -0.023499999999999993" damping="0.1" limited="false" actuatorfrclimited="false"/>
                        <inertial pos="0 0 0" quat="0.711549 0.711549 0 0 " mass="0.001" diaginertia="0.00001 0.00001 0.00001" />
                        <geom size="0.08" quat="1 0 0 0" type="sphere" rgba="0.2 0.2 0.2 1" contype="1" conaffinity="0" group="3"/>
                    </body>
    
                    <body name="rear_left_roller_7_link" pos="-0.03210159698893432 0.0 -0.03210159698893429">
                        <joint name="rear_left_slipping_7_joint" type="hinge" pos="0 0 0" axis="0.017203193977868604 0.0435 -0.017203193977868618" damping="0.1" limited="false" actuatorfrclimited="false"/>
                        <inertial pos="0 0 0" quat="0.711549 0.711549 0 0 " mass="0.001" diaginertia="0.00001 0.00001 0.00001" />
                        <geom size="0.08" quat="1 0 0 0" type="sphere" rgba="0.2 0.2 0.2 1" contype="1" conaffinity="0" group="3"/>
                    </body>
    
                    <body name="rear_left_roller_8_link" pos="-0.011750000000000014 0.0 -0.0438515969889343">
                        <joint name="rear_left_slipping_8_joint" type="hinge" pos="0 0 0" axis="0.023500000000000014 0.0435 -0.006296806022131396" damping="0.1" limited="false" actuatorfrclimited="false"/>
                        <inertial pos="0 0 0" quat="0.711549 0.711549 0 0 " mass="0.001" diaginertia="0.00001 0.00001 0.00001" />
                        <geom size="0.08" quat="1 0 0 0" type="sphere" rgba="0.2 0.2 0.2 1" contype="1" conaffinity="0" group="3"/>
                    </body>
    
                    <body name="rear_left_roller_9_link" pos="0.01174999999999998 0.0 -0.043851596988934316">
                        <joint name="rear_left_slipping_9_joint" type="hinge" pos="0 0 0" axis="0.023499999999999976 0.0435 0.006296806022131368" damping="0.1" limited="false" actuatorfrclimited="false"/>
                        <inertial pos="0 0 0" quat="0.711549 0.711549 0 0 " mass="0.001" diaginertia="0.00001 0.00001 0.00001" />
                        <geom size="0.08" quat="1 0 0 0" type="sphere" rgba="0.2 0.2 0.2 1" contype="1" conaffinity="0" group="3"/>
                    </body>
    
                    <body name="rear_left_roller_10_link" pos="0.032101596988934285 0.0 -0.032101596988934326">
                        <joint name="rear_left_slipping_10_joint" type="hinge" pos="0 0 0" axis="0.017203193977868635 0.0435 0.01720319397786861" damping="0.1" limited="false" actuatorfrclimited="false"/>
                        <inertial pos="0 0 0" quat="0.711549 0.711549 0 0 " mass="0.001" diaginertia="0.00001 0.00001 0.00001" />
                        <geom size="0.08" quat="1 0 0 0" type="sphere" rgba="0.2 0.2 0.2 1" contype="1" conaffinity="0" group="3"/>
                    </body>
    
                    <body name="rear_left_roller_11_link" pos="0.0438515969889343 0.0 -0.01175000000000001">
                        <joint name="rear_left_slipping_11_joint" type="hinge" pos="0 0 0" axis="0.006296806022131396 0.0435 0.02350000000000002" damping="0.1" limited="false" actuatorfrclimited="false"/>
                        <inertial pos="0 0 0" quat="0.711549 0.711549 0 0 " mass="0.001" diaginertia="0.00001 0.00001 0.00001" />
                        <geom size="0.08" quat="1 0 0 0" type="sphere" rgba="0.2 0.2 0.2 1" contype="1" conaffinity="0" group="3"/>
                    </body>
                </body>
            </body>
        </body>
    </worldbody>

    <actuator>
        <velocity name="front_right_wheel" joint="front_right_wheel" kv="140" forcerange="-500 500" ctrlrange="-20 20" />
        <velocity name="front_left_wheel"  joint="front_left_wheel"  kv="140" forcerange="-500 500" ctrlrange="-20 20" />
        <velocity name="rear_right_wheel"  joint="rear_right_wheel"  kv="140" forcerange="-500 500" ctrlrange="-20 20" />
        <velocity name="rear_left_wheel"   joint="rear_left_wheel"   kv="140" forcerange="-500 500" ctrlrange="-20 20" />
    </actuator>

    <sensor> 
        <framepos    name="position_sensor"         objtype="site" objname="xls_site"/> 
        <framequat   name="orientation_sensor"      objtype="site" objname="xls_site"/> 
        <framelinvel name="linear_velocity_sensor"  objtype="site" objname="xls_site"/> 
        <frameangvel name="angular_velocity_sensor" objtype="site" objname="xls_site"/> 
    </sensor>

</mujoco>